<?xml version="1.0" ?>

<robot name="panda" xmlns:xacro="http://www.ros.org/wiki/xacro">

  <material name="Blue">
    <color rgba="0 0.1 1.0 1.0"/>
  </material>
  <material name="Red">
    <color rgba="1.0 0.0 0.0 1.0"/>
  </material>
  <material name="TransparentRed">
    <color rgba="0.9 0 0.2 0.5"/>
  </material>

  <!-- connect arm to world -->
    <link name="world"/>
    <joint name="world_joint" type="fixed">
      <parent link="world"/>
      <child link="fixed_base"/>
      <origin rpy="0.0 0.0 -3.14" xyz="0.0 0.0 0.0"/>
    </joint>

  <link name="fixed_base">
  	<inertial>
      <origin rpy="0 0 0" xyz="0 0 0.05"/>
       <mass value="2.9"/>
       <inertia ixx="0.1" ixy="0" ixz="0" iyy="0.1" iyz="0" izz="0.1"/>
    </inertial>
    <visual>
      <geometry>
        <mesh filename="../collision/link0.obj"/>
      </geometry>
      <material name="panda_white">
    		<color rgba="1. 1. 1. 1."/>
  		</material>
    </visual>
    <collision>
      <geometry>
        <mesh filename="../collision/link0.obj"/>
      </geometry>
      <material name="panda_white"/>
    </collision>
  </link>

  <link name="panda_link1">
  	<inertial>
      <origin rpy="0 0 0" xyz="0 -0.04 -0.05"/>
       <mass value="2.7"/>
       <inertia ixx="0.1" ixy="0" ixz="0" iyy="0.1" iyz="0" izz="0.1"/>
    </inertial>
    <visual>
      <geometry>
        <mesh filename="visual/link1.obj"/>
      </geometry>
      <material name="panda_white"/>
    </visual>
    <collision>
      <geometry>
        <mesh filename="../collision/link1.obj"/>
      </geometry>
      <material name="panda_white"/>
    </collision>
  </link>

  <joint name="panda_joint1" type="revolute">
    <safety_controller k_position="100.0" k_velocity="40.0" soft_lower_limit="-2.8973" soft_upper_limit="2.8973"/>
    <origin rpy="0 0 0" xyz="0 0 0.333"/>
    <parent link="fixed_base"/>
    <child link="panda_link1"/>
    <axis xyz="0 0 1"/>
    <limit effort="87" lower="-100" upper="100" velocity="2.1750"/>
  </joint>

  <link name="panda_link2">
  	<inertial>
      <origin rpy="0 0 0" xyz="0 -0.04 0.06"/>
       <mass value="2.73"/>
       <inertia ixx="0.1" ixy="0" ixz="0" iyy="0.1" iyz="0" izz="0.1"/>
    </inertial>
    <visual>
      <geometry>
        <mesh filename="visual/link2.obj"/>
      </geometry>
      <material name="panda_white"/>
    </visual>
    <collision>
      <geometry>
        <mesh filename="../collision/link2.obj"/>
      </geometry>
      <material name="panda_white"/>
    </collision>
  </link>

  <joint name="panda_joint2" type="revolute">
    <safety_controller k_position="100.0" k_velocity="40.0" soft_lower_limit="-1.7628" soft_upper_limit="1.7628"/>
    <origin rpy="-1.57079632679 0 0" xyz="0 0 0"/>
    <parent link="panda_link1"/>
    <child link="panda_link2"/>
    <axis xyz="0 0 1"/>
    <limit effort="87" lower="-100" upper="100" velocity="2.1750"/>
  </joint>

  <link name="panda_link3">
	  <inertial>
      <origin rpy="0 0 0" xyz="0.01 0.01 -0.05"/>
       <mass value="2.04"/>
       <inertia ixx="0.1" ixy="0" ixz="0" iyy="0.1" iyz="0" izz="0.1"/>
    </inertial>
    <visual>
      <geometry>
        <mesh filename="visual/link3.obj"/>
      </geometry>
      <material name="panda_red">
    		<color rgba="1. 1. 1. 1."/>
  		</material>
    </visual>
    <collision>
      <geometry>
        <mesh filename="../collision/link3.obj"/>
      </geometry>
    </collision>
  </link>

  <joint name="panda_joint3" type="revolute">
    <safety_controller k_position="100.0" k_velocity="40.0" soft_lower_limit="-2.8973" soft_upper_limit="2.8973"/>
    <origin rpy="1.57079632679 0 0" xyz="0 -0.316 0"/>
    <parent link="panda_link2"/>
    <child link="panda_link3"/>
    <axis xyz="0 0 1"/>
    <limit effort="87" lower="-100" upper="100" velocity="2.1750"/>
  </joint>

  <link name="panda_link4">
  	<inertial>
      <origin rpy="0 0 0" xyz="-0.03 0.03 0.02"/>
       <mass value="2.08"/>
       <inertia ixx="0.1" ixy="0" ixz="0" iyy="0.1" iyz="0" izz="0.1"/>
    </inertial>
    <visual>
      <geometry>
        <mesh filename="visual/link4.obj"/>
      </geometry>
      <material name="panda_white"/>
    </visual>
    <collision>
      <geometry>
        <mesh filename="../collision/link4.obj"/>
      </geometry>
      <material name="panda_white"/>
    </collision>
  </link>

  <joint name="panda_joint4" type="revolute">
    <safety_controller k_position="100.0" k_velocity="40.0" soft_lower_limit="-3.0718" soft_upper_limit="-0.0698"/>
    <origin rpy="1.57079632679 0 0" xyz="0.0825 0 0"/>
    <parent link="panda_link3"/>
    <child link="panda_link4"/>
    <axis xyz="0 0 1"/>
    <limit effort="87" lower="-100" upper="100" velocity="2.1750"/>
  </joint>

  <link name="panda_link5">
  	<inertial>
      <origin rpy="0 0 0" xyz="0 0.04 -0.12"/>
       <mass value="3"/>
       <inertia ixx="0.1" ixy="0" ixz="0" iyy="0.1" iyz="0" izz="0.1"/>
    </inertial>
    <visual>
      <geometry>
        <mesh filename="visual/link5.obj"/>
      </geometry>
      <material name="panda_white"/>
    </visual>
    <collision>
      <geometry>
        <mesh filename="../collision/link5.obj"/>
      </geometry>
      <material name="panda_white"/>
    </collision>
  </link>

  <joint name="panda_joint5" type="revolute">
    <safety_controller k_position="100.0" k_velocity="40.0" soft_lower_limit="-2.8973" soft_upper_limit="2.8973"/>
    <origin rpy="-1.57079632679 0 0" xyz="-0.0825 0.384 0"/>
    <parent link="panda_link4"/>
    <child link="panda_link5"/>
    <axis xyz="0 0 1"/>
    <limit effort="12" lower="-100" upper="100" velocity="2.6100"/>
  </joint>

  <link name="panda_link6">
  	<inertial>
      <origin rpy="0 0 0" xyz="0.04 0 0"/>
       <mass value="1.3"/>
       <inertia ixx="0.1" ixy="0" ixz="0" iyy="0.1" iyz="0" izz="0.1"/>
    </inertial>
    <visual>
      <geometry>
        <mesh filename="visual/link6.obj"/>
      </geometry>
      <material name="panda_white"/>
    </visual>
    <collision>
      <geometry>
        <mesh filename="../collision/link6.obj"/>
      </geometry>
      <material name="panda_white"/>
    </collision>
  </link>

  <joint name="panda_joint6" type="revolute">
    <safety_controller k_position="100.0" k_velocity="40.0" soft_lower_limit="-0.0175" soft_upper_limit="3.7525"/>
    <origin rpy="1.57079632679 0 0" xyz="0 0 0"/>
    <parent link="panda_link5"/>
    <child link="panda_link6"/>
    <axis xyz="0 0 1"/>
    <limit effort="12" lower="-100" upper="100" velocity="2.6100"/>
  </joint>

  <link name="panda_link7">
  	<inertial>
      <origin rpy="0 0 0" xyz="0 0 0.08"/>
       <mass value=".2"/>
       <inertia ixx="0.1" ixy="0" ixz="0" iyy="0.1" iyz="0" izz="0.1"/>
    </inertial>
    <visual>
      <geometry>
        <mesh filename="../collision/link7.obj"/>
      </geometry>
      <material name="panda_white"/>
    </visual>
    <collision>
      <geometry>
        <mesh filename="../collision/link7.obj"/>
      </geometry>
      <material name="panda_white"/>
    </collision>
  </link>

  <joint name="panda_joint7" type="revolute">
    <safety_controller k_position="100.0" k_velocity="40.0" soft_lower_limit="-2.8973" soft_upper_limit="2.8973"/>
    <origin rpy="1.57079632679 0 0" xyz="0.088 0 0"/>
    <parent link="panda_link6"/>
    <child link="panda_link7"/>
    <axis xyz="0 0 1"/>
    <limit effort="12" lower="-100" upper="100" velocity="2.6100"/>
  </joint>


  <!-- End Effector -->

  <link name="ee_link">
    <visual>
      <origin rpy="0 0 0" xyz="0 0 0"/>
      <geometry>
        <sphere radius="0.001"/>
      </geometry>
       <material name="Red"/>
    </visual>
    <collision>
      <geometry>
        <sphere radius="0.01"/>
      </geometry>
      <origin rpy="0 0 0" xyz="0.0 0 0"/>
    </collision>
  	 <inertial>
       <origin rpy="0 0 0" xyz="0 0 0"/>
       <mass value="0.0"/>
       <inertia ixx="0.1" ixy="0" ixz="0" iyy="0.1" iyz="0" izz="0.1"/>
    </inertial>
  </link>

  <joint name="ee_joint" type="fixed">
    <origin rpy="0.0 0.0 0.0" xyz="0 0 0.107"/>
    <parent link="panda_link7"/>
    <child link="ee_link"/>
    <axis xyz="0 0 0"/>
  </joint>


    <!-- TacTip -->

    <link name="tactip_body_link">
      <inertial>
        <origin rpy="0 0 0" xyz="0 0 0"/>
         <mass value="0.25"/>
         <inertia ixx="0.001" ixy="0" ixz="0" iyy="0.001" iyz="0" izz="0.001"/>
      </inertial>
      <visual>
        <origin rpy="0 0 0" xyz="0 0 0"/>
        <geometry>
  				<mesh filename="../tactip/standard_tactip/body/tactip_body.obj" scale="1.0 1.0 1.0"/>
        </geometry>
         <material name="whitish">
          <color rgba="0.8 0.8 0.8 1.0"/>
        </material>
      </visual>
      <collision>
        <origin rpy="0 0 0" xyz="0 0 0"/>
        <geometry>
  				<mesh filename="../tactip/standard_tactip/body/tactip_body.obj" scale="1.0 1.0 1.0"/>
        </geometry>
      </collision>
    </link>

    <joint name="tactip_ee_joint" type="fixed">
      <parent link="ee_link"/>
      <child link="tactip_body_link"/>
      <origin rpy="0.0 0.0 -1.57" xyz="0.0 0.0 0.0"/>
    </joint>

    <link name="tactip_tip_link">
      <contact>
        <friction_anchor/>
        <lateral_friction value="1.0"/>
      </contact>
      <inertial>
        <origin rpy="0 0 0" xyz="0 0 0"/>
         <mass value="0.01"/>
         <inertia ixx="1" ixy="0" ixz="0" iyy="1" iyz="0" izz="1"/>
      </inertial>
      <visual>
        <origin rpy="0 0 0" xyz="0 0 0"/>
        <geometry>
          <mesh filename="../tactip/standard_tactip/tip/skin.obj" scale="1.0 1.0 1.0"/>
        </geometry>
         <material name="black">
          <color rgba="0.0 0.0 0.0 1.0"/>
        </material>
      </visual>
      <collision>
        <origin rpy="0 0 0" xyz="0 0 0"/>
        <geometry>
          <mesh filename="../tactip/standard_tactip/tip/core.obj" scale="1 1 1"/>
        </geometry>
      </collision>
    </link>

    <joint name="tactip_tip_to_body" type="fixed">
       <origin rpy="1.57 0 0" xyz="0 0 0.065"/>
       <axis xyz="0 1 0"/>
       <parent link="tactip_body_link"/>
       <child link="tactip_tip_link"/>
    </joint>

    <!-- TCP -->
    <link name="tcp_link">
      <visual>
        <origin rpy="0 0 0" xyz="0 0 0"/>
        <geometry>
          <sphere radius="0.001"/>
        </geometry>
         <material name="TransparentRed"/>
      </visual>
      <inertial>
        <mass value="0.0"/>
        <origin rpy="0.0 0.0 1.57" xyz="0.0 0.0 0.0"/>
        <inertia ixx="1.0" ixy="0.0" ixz="0.0" iyy="1.0" iyz="0.0" izz="1.0"/>
      </inertial>
    </link>

    <joint name="tcp_joint" type="fixed">
      <parent link="tactip_body_link"/>
      <child link="tcp_link"/>
      <origin rpy="0 0 0" xyz="0.0 0.0 0.085"/>
    </joint>


</robot>
